Workbook

Sheet 0_说明
A1: 文远知行｜2026-09研究底稿｜用户指定版本 Sonus
A2: 金额展示为人民币百万，同行表USD百万；原始输入保留千元。
A3: 蓝字=原始输入，黑字=同表公式，绿字=跨表公式；黄色=假设/待核。
A4: 期间：FY2021–FY2025及H1 2023–2026；仅两份独立20-F，以招股书补历史。
A5: FY2021完整集团资产负债表未取得，空缺标“未取得”，不将VIE资产负债表替代集团。
A6: 文远全期IFRS；PONY为US GAAP。车辆级UE不等于公司级FCF。
A7: 最新三表：2026中报PDF47、49–50、53–54；审阅而非审计。
A8: FCF=OCF−购置固定资产−购置无形资产；另列扣租赁本金/利息及贷款利息的压力口径。
A9: 历史半年OCF采用较新HK招股书：H1 2024为−327.180，旧美招股书为−327.558；差额仍待附注解释。
A10: 归母损益不等于IPO前普通股股东损益：FY2023视同分派32.767未扣在归母行。
A11: 所有输入均在7_原始输入及6_取数日志；所有派生数均为公式。
A12: 三锚点：FY2024收入/归母/总资产与SEC ifrs-full逐值一致；SEC缓存未覆盖最新年度，不宣称最新也已双源核。
... A18: 原始来源、SHA256见source_manifest.json；公式测试及勾稽见workbook_validation.json。

Sheet 1_分部拆解
A1: 收入拆解（人民币百万） | B1: FY2021 | C1: FY2022 | D1: FY2023 | E1: FY2024 | F1: FY2025 | G1: H12026 | H1: 口径
A2: 产品 | B2: ='7_原始输入'!B7/1000 -> 101.597 | C2: ='7_原始输入'!B8/1000 -> 337.717 | D2: ='7_原始输入'!B9/1000 -> 54.19 | E2: ='7_原始输入'!B10/1000 -> 87.71 | F2: ='7_原始输入'!B11/1000 -> 359.843 | G2: ='7_原始输入'!B104/1000 -> 112.783
A3: 服务 | B3: ='7_原始输入'!B12/1000 -> 36.575 | C3: ='7_原始输入'!B13/1000 -> 189.826 | D3: ='7_原始输入'!B14/1000 -> 347.654 | E3: ='7_原始输入'!B15/1000 -> 273.424 | F3: ='7_原始输入'!B16/1000 -> 324.744 | G3: ='7_原始输入'!B108/1000 -> 233.074
A4: 收入 | B4: ='7_原始输入'!B2/1000 -> 138.172 | C4: ='7_原始输入'!B3/1000 -> 527.543 | D4: ='7_原始输入'!B4/1000 -> 401.844 | E4: ='7_原始输入'!B5/1000 -> 361.134 | F4: ='7_原始输入'!B6/1000 -> 684.587 | G4: ='7_原始输入'!B100/1000 -> 345.857
A6: 产品占比 | B6: =B2/B4 -> 0.73529369 | C6: =C2/C4 -> 0.64016962 | D6: =D2/D4 -> 0.13485333 | E6: =E2/E4 -> 0.24287384 | F6: =F2/F4 -> 0.52563516 | G6: =G2/G4 -> 0.3260972
A7: 服务占比 | B7: =B3/B4 -> 0.26470631 | C7: =C3/C4 -> 0.35983038 | D7: =D3/D4 -> 0.86514667 | E7: =E3/E4 -> 0.75712616 | F7: =F3/F4 -> 0.47436484 | G7: =G3/G4 -> 0.6739028
A9: 收入勾稽差 | B9: =B2+B3-B4 -> 0 | C9: =C2+C3-C4 -> 0 | D9: =D2+D3-D4 -> 0 | E9: =E2+E3-E4 -> -5.6843419e-14 | F9: =F2+F3-F4 -> 0 | G9: =G2+G3-G4 -> 0
A11: 业务线而非独立经营分部；Robotaxi含车辆/技术支持，不是纯车费
A12: 车型业务（人民币百万） | B12: FY2023 | C12: FY2024 | D12: FY2025 | E12: FY2025占比
A13: Robotaxi及相关服务 | B13: ='7_原始输入'!B317/1000 -> 29.379 | C13: ='7_原始输入'!B318/1000 -> 47.832 | D13: ='7_原始输入'!B319/1000 -> 147.993 | E13: =D13/F4 -> 0.21617851
A14: Robobus | B14: ='7_原始输入'!B320/1000 -> 94.914 | C14: ='7_原始输入'!B321/1000 -> 79.688 | D14: ='7_原始输入'!B322/1000 -> 231.473 | E14: =D14/F4 -> 0.33812065
A15: Robosweeper | B15: ='7_原始输入'!B323/1000 -> 7.642 | C15: ='7_原始输入'!B324/1000 -> 55.32 | D15: ='7_原始输入'!B325/1000 -> 96.083 | E15: =D15/F4 -> 0.14035177
A16: Robovan | B16: ='7_原始输入'!B326/1000 -> 7.54 | C16: ='7_原始输入'!B327/1000 -> 13.393 | D16: ='7_原始输入'!B328/1000 -> 10.493 | E16: =D16/F4 -> 0.015327489
A17: 其他技术服务 | B17: ='7_原始输入'!B329/1000 -> 262.369 | C17: ='7_原始输入'!B330/1000 -> 164.901 | D17: ='7_原始输入'!B331/1000 -> 198.545 | E17: =D17/F4 -> 0.29002158
A18: 业务线合计 | B18: =SUM(B13:B17) -> 401.844 | C18: =SUM(C13:C17) -> 361.134 | D18: =SUM(D13:D17) -> 684.587
A21: 最新分类（不可硬接车型） | B21: H12025 | C21: H12026 | D21: 同比 | E21: H12026占比
A22: L4 | B22: ='7_原始输入'!B335/1000 -> 123.932 | C22: ='7_原始输入'!B336/1000 -> 179.475 | D22: =C22/B22-1 -> 0.44817319 | E22: =C22/G4 -> 0.51892834
A23: 其他业务 | B23: ='7_原始输入'!B337/1000 -> 75.683 | C23: ='7_原始输入'!B338/1000 -> 166.382 | D23: =C23/B23-1 -> 1.1984065 | E23: =C23/G4 -> 0.48107166
A24: 海外 | B24: ='7_原始输入'!B339/1000 -> 46.929 | C24: ='7_原始输入'!B340/1000 -> 119.299 | D24: =C24/B24-1 -> 1.5421168 | E24: =C24/G4 -> 0.34493736
A26: 分业务毛利率/纯车费/单车完整成本：未披露，不能用集团毛利率分摊

Sheet 2_利润表五年
A1: 利润表（人民币百万） | B1: FY2021 | C1: FY2022 | D1: FY2023 | E1: FY2024 | F1: FY2025 | G1: H12026 | H1: TTM至2026-06
A2: 收入 | B2: ='7_原始输入'!B2/1000 -> 138.172 | C2: ='7_原始输入'!B3/1000 -> 527.543 | D2: ='7_原始输入'!B4/1000 -> 401.844 | E2: ='7_原始输入'!B5/1000 -> 361.134 | F2: ='7_原始输入'!B6/1000 -> 684.587 | G2: ='7_原始输入'!B100/1000 -> 345.857 | H2: =('7_原始输入'!B6-'7_原始输入'!B99+'7_原始输入'!B100)/1000 -> 830.829
A3: 毛利 | B3: ='7_原始输入'!B17/1000 -> 51.66 | C3: ='7_原始输入'!B18/1000 -> 232.545 | D3: ='7_原始输入'!B19/1000 -> 183.476 | E3: ='7_原始输入'!B20/1000 -> 110.715 | F3: ='7_原始输入'!B21/1000 -> 206.822 | G3: ='7_原始输入'!B112/1000 -> 126.473 | H3: =('7_原始输入'!B21-'7_原始输入'!B111+'7_原始输入'!B112)/1000 -> 272.236
A4: 销售行政 | B4: =('7_原始输入'!B32+'7_原始输入'!B27)/1000 -> -119.344 | C4: =('7_原始输入'!B33+'7_原始输入'!B28)/1000 -> -260.81 | D4: =('7_原始输入'!B34+'7_原始输入'!B29)/1000 -> -666.816 | E4: =('7_原始输入'!B35+'7_原始输入'!B30)/1000 -> -1192.368 | F4: =('7_原始输入'!B36+'7_原始输入'!B31)/1000 -> -669.688 | G4: =('7_原始输入'!B124+'7_原始输入'!B120)/1000 -> -203.957
A5: 融资成本 | B5: ='7_原始输入'!B62/1000 -> -6.917 | C5: ='7_原始输入'!B63/1000 -> -4.202 | D5: ='7_原始输入'!B64/1000 -> -3.49 | E5: ='7_原始输入'!B65/1000 -> -3.451 | F5: ='7_原始输入'!B66/1000 -> -9.128 | G5: ='7_原始输入'!B136/1000 -> -5.089 | H5: =('7_原始输入'!B66-'7_原始输入'!B135+'7_原始输入'!B136)/1000 -> -10.925
A6: 研发 | B6: ='7_原始输入'!B22/1000 -> -443.178 | C6: ='7_原始输入'!B23/1000 -> -758.565 | D6: ='7_原始输入'!B24/1000 -> -1058.395 | E6: ='7_原始输入'!B25/1000 -> -1091.357 | F6: ='7_原始输入'!B26/1000 -> -1372.191 | G6: ='7_原始输入'!B116/1000 -> -797.654 | H6: =('7_原始输入'!B26-'7_原始输入'!B115+'7_原始输入'!B116)/1000 -> -1525.21
A7: 税前亏损 | B7: ='7_原始输入'!B42/1000 -> -1007.251 | C7: ='7_原始输入'!B43/1000 -> -1298.496 | D7: ='7_原始输入'!B44/1000 -> -1946.235 | E7: ='7_原始输入'!B45/1000 -> -2510.94 | F7: ='7_原始输入'!B46/1000 -> -1650.8 | G7: 未录入；不估填
A8: 归母净亏损 | B8: ='7_原始输入'!B47/1000 -> -1007.251 | C8: ='7_原始输入'!B48/1000 -> -1298.496 | D8: ='7_原始输入'!B49/1000 -> -1949.101 | E8: ='7_原始输入'!B50/1000 -> -2516.808 | F8: ='7_原始输入'!B51/1000 -> -1654.9 | G8: ='7_原始输入'!B132/1000 -> -789.75 | H8: =('7_原始输入'!B51-'7_原始输入'!B131+'7_原始输入'!B132)/1000 -> -1653.133
A9: 经营亏损 | B9: ='7_原始输入'!B37/1000 -> -500.496 | C9: ='7_原始输入'!B38/1000 -> -779.23 | D9: ='7_原始输入'!B39/1000 -> -1566.202 | E9: ='7_原始输入'!B40/1000 -> -2185.183 | F9: ='7_原始输入'!B41/1000 -> -1846.77 | G9: ='7_原始输入'!B128/1000 -> -852.91 | H9: =('7_原始输入'!B41-'7_原始输入'!B127+'7_原始输入'!B128)/1000 -> -1809.603
A10: 股权支付 | B10: ='7_原始输入'!B52/1000 -> 55.959 | C10: ='7_原始输入'!B53/1000 -> 325.429 | D10: ='7_原始输入'!B54/1000 -> 931.784 | E10: ='7_原始输入'!B55/1000 -> 1187.867 | F10: ='7_原始输入'!B56/1000 -> 449.983 | G10: 未录入；不估填
A11: 调整后亏损 | B11: ='7_原始输入'!B57/1000 -> -426.757 | C11: ='7_原始输入'!B58/1000 -> -401.683 | D11: ='7_原始输入'!B59/1000 -> -501.68 | E11: ='7_原始输入'!B60/1000 -> -801.853 | F11: ='7_原始输入'!B61/1000 -> -1246.739 | G11: 未录入；不估填
A12: 毛利率 | B12: =B3/B2 -> 0.37388183 | C12: =C3/C2 -> 0.44080767 | D12: =D3/D2 -> 0.45658514 | E12: =E3/E2 -> 0.30657595 | F12: =F3/F2 -> 0.30211208 | G12: =G3/G2 -> 0.36568004 | H12: =H3/H2 -> 0.32766791
A13: 研发/收入 | B13: =-B6/B2 -> 3.2074371 | C13: =-C6/C2 -> 1.4379207 | D13: =-D6/D2 -> 2.6338455 | E13: =-E6/E2 -> 3.0220278 | F13: =-F6/F2 -> 2.004407 | G13: =-G6/G2 -> 2.3063116
A14: 营业亏损率 | B14: =B9/B2 -> -3.6222679 | C14: =C9/C2 -> -1.4770929 | D14: =D9/D2 -> -3.8975374 | E14: =E9/E2 -> -6.0508925 | F14: =F9/F2 -> -2.6976411 | G14: =G9/G2 -> -2.466077
A15: 收入同比 | B15: 未取得FY2020 | C15: =C2/B2-1 -> 2.8180167 | D15: =D2/C2-1 -> -0.23827252 | E15: =E2/D2-1 -> -0.10130797 | F15: =F2/E2-1 -> 0.89565923 | G15: ='7_原始输入'!B100/'7_原始输入'!B99-1 -> 0.73262029
A18: 调整后亏损为公司Non-IFRS，不等于A股扣非；FY2025净亏损改善但调整后亏损扩大。

Sheet 3_现金流照妖镜
A1: 现金流（人民币百万） | B1: FY2021 | C1: FY2022 | D1: FY2023 | E1: FY2024 | F1: FY2025 | G1: H12026 | H1: 五年合计 | I1: TTM至2026-06
A2: OCF | B2: ='7_原始输入'!B67/1000 -> -506.667 | C2: ='7_原始输入'!B68/1000 -> -670.381 | D2: ='7_原始输入'!B69/1000 -> -474.89 | E2: ='7_原始输入'!B70/1000 -> -593.595 | F2: ='7_原始输入'!B71/1000 -> -1321.734 | G2: ='7_原始输入'!B140/1000 -> -715.677 | H2: =SUM(B2:F2) -> -3567.267 | I2: =('7_原始输入'!B71-'7_原始输入'!B139+'7_原始输入'!B140)/1000 -> -1374.015
A3: 固定资产购置 | B3: ='7_原始输入'!B72/1000 -> 25.156 | C3: ='7_原始输入'!B73/1000 -> 80.812 | D3: ='7_原始输入'!B74/1000 -> 36.65 | E3: ='7_原始输入'!B75/1000 -> 84.004 | F3: ='7_原始输入'!B76/1000 -> 247.598 | G3: ='7_原始输入'!B144/1000 -> 235.442 | H3: =SUM(B3:F3) -> 474.22 | I3: =('7_原始输入'!B76-'7_原始输入'!B143+'7_原始输入'!B144)/1000 -> 348.686
A4: 无形资产购置 | B4: ='7_原始输入'!B77/1000 -> 0.481 | C4: ='7_原始输入'!B78/1000 -> 1.881 | D4: ='7_原始输入'!B79/1000 -> 0.304 | E4: ='7_原始输入'!B80/1000 -> 1.504 | F4: ='7_原始输入'!B81/1000 -> 0.848 | G4: ='7_原始输入'!B148/1000 -> 0.808 | H4: =SUM(B4:F4) -> 5.018 | I4: =('7_原始输入'!B81-'7_原始输入'!B147+'7_原始输入'!B148)/1000 -> 1.539
A5: 资本开支合计 | B5: =B3+B4 -> 25.637 | C5: =C3+C4 -> 82.693 | D5: =D3+D4 -> 36.954 | E5: =E3+E4 -> 85.508 | F5: =F3+F4 -> 248.446 | G5: =G3+G4 -> 236.25 | H5: =SUM(B5:F5) -> 479.238 | I5: =F5-D17+G5 -> 350.225
A6: FCF | B6: =B2-B5 -> -532.304 | C6: =C2-C5 -> -753.074 | D6: =D2-D5 -> -511.844 | E6: =E2-E5 -> -679.103 | F6: =F2-F5 -> -1570.18 | G6: =G2-G5 -> -951.927 | H6: =SUM(B6:F6) -> -4046.505 | I6: =F6-D18+G6 -> -1724.24
A7: 投资现金流 | B7: ='7_原始输入'!B82/1000 -> 460.903 | C7: ='7_原始输入'!B83/1000 -> -2202.414 | D7: ='7_原始输入'!B84/1000 -> -546.944 | E7: ='7_原始输入'!B85/1000 -> 325.505 | F7: ='7_原始输入'!B86/1000 -> 1505.881 | G7: ='7_原始输入'!B152/1000 -> -960.615 | H7: =SUM(B7:F7) -> -457.069 | I7: =('7_原始输入'!B86-'7_原始输入'!B151+'7_原始输入'!B152)/1000 -> 326.567
A8: 融资现金流 | B8: ='7_原始输入'!B87/1000 -> 2603.053 | C8: ='7_原始输入'!B88/1000 -> 2184.588 | D8: ='7_原始输入'!B89/1000 -> 446.954 | E8: ='7_原始输入'!B90/1000 -> 2823.875 | F8: ='7_原始输入'!B91/1000 -> 2296.444 | G8: ='7_原始输入'!B156/1000 -> -544.316 | H8: =SUM(B8:F8) -> 10354.914 | I8: =('7_原始输入'!B91-'7_原始输入'!B155+'7_原始输入'!B156)/1000 -> 1748.229
A9: 现金 | B9: ='7_原始输入'!B92/1000 -> 2725.568 | C9: ='7_原始输入'!B93/1000 -> 2233.691 | D9: ='7_原始输入'!B94/1000 -> 1661.152 | E9: ='7_原始输入'!B95/1000 -> 4268.3 | F9: ='7_原始输入'!B96/1000 -> 6666.304 | G9: ='7_原始输入'!B160/1000 -> 4275.014 | H9: 时点值不可相加 | I9: =G9 -> 4275.014
A13: 历年半年（人民币百万） | B13: H12023 | C13: H12024 | D13: H12025 | E13: H12026
A14: OCF | B14: ='7_原始输入'!B137/1000 -> -223.742 | C14: ='7_原始输入'!B138/1000 -> -327.18 | D14: ='7_原始输入'!B139/1000 -> -663.396 | E14: ='7_原始输入'!B140/1000 -> -715.677
A15: 固定资产购置 | B15: ='7_原始输入'!B141/1000 -> 15.906 | C15: ='7_原始输入'!B142/1000 -> 33.272 | D15: ='7_原始输入'!B143/1000 -> 134.354 | E15: ='7_原始输入'!B144/1000 -> 235.442
A16: 无形资产购置 | B16: ='7_原始输入'!B145/1000 -> 0.127 | C16: ='7_原始输入'!B146/1000 -> 0 | D16: ='7_原始输入'!B147/1000 -> 0.117 | E16: ='7_原始输入'!B148/1000 -> 0.808
A17: 资本开支合计 | B17: =B15+B16 -> 16.033 | C17: =C15+C16 -> 33.272 | D17: =D15+D16 -> 134.471 | E17: =E15+E16 -> 236.25
A18: FCF | B18: =B14-B17 -> -239.775 | C18: =C14-C17 -> -360.452 | D18: =D14-D17 -> -797.867 | E18: =E14-E17 -> -951.927
A19: 投资现金流 | B19: ='7_原始输入'!B149/1000 -> -555.576 | C19: ='7_原始输入'!B150/1000 -> 453.236 | D19: ='7_原始输入'!B151/1000 -> 218.699 | E19: ='7_原始输入'!B152/1000 -> -960.615
A20: 融资现金流 | B20: ='7_原始输入'!B153/1000 -> 193.356 | C20: ='7_原始输入'!B154/1000 -> -8.877 | D20: ='7_原始输入'!B155/1000 -> 3.899 | E20: ='7_原始输入'!B156/1000 -> -544.316
A21: 现金 | B21: ='7_原始输入'!B157/1000 -> 1659.97 | C21: ='7_原始输入'!B158/1000 -> 1828.943 | D21: ='7_原始输入'!B159/1000 -> 3836.137 | E21: ='7_原始输入'!B160/1000 -> 4275.014
A24: H1 2026回购（不进FCF） | B24: ='7_原始输入'!B266/1000 -> 684.809
A25: H1 2026租赁本金/利息+贷款利息 | B25: =('7_原始输入'!B267+'7_原始输入'!B268+'7_原始输入'!B269)/1000 -> 29.619
A26: H1 2026全现金支出压力（不含融资/资金调配） | B26: =-G6+B24+B25 -> 1666.355
A27: 现金桥勾稽差 | B27: =F9+G2+G7+G8+'7_原始输入'!B270/1000-G9 -> 9.094947e-13
A29: 亏损/亏损的OCF净利比不作利润质量判断；H1 2024后列OCF与融资净额分别变378，净现金变动不变。

Sheet 4_资产负债偿债
A1: 资产负债（人民币百万） | B1: FY2021 | C1: FY2022 | D1: FY2023 | E1: FY2024 | F1: FY2025 | G1: H12026 | H1: 口径
A2: 总资产 | B2: 未取得 | C2: ='7_原始输入'!B161/1000 -> 5385.391 | D2: ='7_原始输入'!B162/1000 -> 5614.258 | E2: ='7_原始输入'!B163/1000 -> 7693.77 | F2: ='7_原始输入'!B164/1000 -> 8935.925 | G2: ='7_原始输入'!B165/1000 -> 7755.416
A3: 归母权益 | B3: 未取得 | C3: ='7_原始输入'!B166/1000 -> -2082.116 | D3: ='7_原始输入'!B167/1000 -> -3051.918 | E3: ='7_原始输入'!B168/1000 -> 7066.019 | F3: ='7_原始输入'!B169/1000 -> 7900.174 | G3: ='7_原始输入'!B170/1000 -> 6395.302
A4: 现金 | B4: ='7_原始输入'!B92/1000 -> 2725.568 | C4: ='7_原始输入'!B93/1000 -> 2233.691 | D4: ='7_原始输入'!B94/1000 -> 1661.152 | E4: ='7_原始输入'!B95/1000 -> 4268.3 | F4: ='7_原始输入'!B96/1000 -> 6666.304 | G4: ='7_原始输入'!B160/1000 -> 4275.014
A5: 短期贷款 | B5: 未取得 | C5: ='7_原始输入'!B171/1000 -> 0 | D5: ='7_原始输入'!B172/1000 -> 0 | E5: ='7_原始输入'!B173/1000 -> 30.019 | F5: ='7_原始输入'!B174/1000 -> 324.263 | G5: ='7_原始输入'!B175/1000 -> 485.047
A6: 长期贷款 | B6: 未取得 | C6: ='7_原始输入'!B176/1000 -> 0 | D6: ='7_原始输入'!B177/1000 -> 0 | E6: ='7_原始输入'!B178/1000 -> 50.04 | F6: ='7_原始输入'!B179/1000 -> 0 | G6: ='7_原始输入'!B180/1000 -> 0
A7: 租赁流动 | B7: 未取得 | C7: ='7_原始输入'!B181/1000 -> 32.009 | D7: ='7_原始输入'!B182/1000 -> 31.098 | E7: ='7_原始输入'!B183/1000 -> 36.9 | F7: ='7_原始输入'!B184/1000 -> 31.92 | G7: ='7_原始输入'!B185/1000 -> 35.39
A8: 租赁非流动 | B8: 未取得 | C8: ='7_原始输入'!B186/1000 -> 35.864 | D8: ='7_原始输入'!B187/1000 -> 22.309 | E8: ='7_原始输入'!B188/1000 -> 26.059 | F8: ='7_原始输入'!B189/1000 -> 23.241 | G8: ='7_原始输入'!B190/1000 -> 95.397
A9: 贸易应收净额 | B9: 未取得 | C9: ='7_原始输入'!B191/1000 -> 236.39 | D9: ='7_原始输入'!B192/1000 -> 266.933 | E9: ='7_原始输入'!B193/1000 -> 252.607 | F9: ='7_原始输入'!B194/1000 -> 462.135 | G9: ='7_原始输入'!B195/1000 -> 455.765
A10: 合同资产净额 | B10: 未取得 | C10: ='7_原始输入'!B196/1000 -> 92.597 | D10: ='7_原始输入'!B197/1000 -> 82.826 | E10: ='7_原始输入'!B198/1000 -> 28.005 | F10: ='7_原始输入'!B199/1000 -> 23.305 | G10: ='7_原始输入'!B200/1000 -> 23.964
A11: 定期存款 | B11: 未取得 | C11: ='7_原始输入'!B201/1000 -> 1057.292 | D11: ='7_原始输入'!B202/1000 -> 2550.279 | E11: ='7_原始输入'!B203/1000 -> 620.148 | F11: ='7_原始输入'!B204/1000 -> 301.401 | G11: ='7_原始输入'!B205/1000 -> 1099.805
A12: 流动FVTPL | B12: 未取得 | C12: ='7_原始输入'!B206/1000 -> 1218.524 | D12: ='7_原始输入'!B207/1000 -> 317.042 | E12: ='7_原始输入'!B208/1000 -> 1685.146 | F12: ='7_原始输入'!B209/1000 -> 144.252 | G12: ='7_原始输入'!B210/1000 -> 2.293
A13: 非流动FVTPL | B13: 未取得 | C13: 未取得 | D13: ='7_原始输入'!B211/1000 -> 0 | E13: ='7_原始输入'!B212/1000 -> 56.919 | F13: ='7_原始输入'!B213/1000 -> 188.083 | G13: ='7_原始输入'!B214/1000 -> 252.411
A14: 受限现金流动 | B14: 未取得 | C14: ='7_原始输入'!B215/1000 -> 1.393 | D14: ='7_原始输入'!B216/1000 -> 10.194 | E14: ='7_原始输入'!B217/1000 -> 4.814 | F14: ='7_原始输入'!B218/1000 -> 12.91 | G14: ='7_原始输入'!B219/1000 -> 10.42
A15: 受限现金非流动 | B15: 未取得 | C15: ='7_原始输入'!B220/1000 -> 11.004 | D15: ='7_原始输入'!B221/1000 -> 1.575 | E15: ='7_原始输入'!B222/1000 -> 9.669 | F15: ='7_原始输入'!B223/1000 -> 6.487 | G15: ='7_原始输入'!B224/1000 -> 10.988
A16: 存货 | B16: 未取得 | C16: ='7_原始输入'!B225/1000 -> 156.005 | D16: ='7_原始输入'!B226/1000 -> 218.22 | E16: ='7_原始输入'!B227/1000 -> 204.705 | F16: ='7_原始输入'!B228/1000 -> 321.021 | G16: ='7_原始输入'!B229/1000 -> 439.112
A17: 总负债 | B17: 未取得 | C17: ='7_原始输入'!B230/1000 -> 7467.507 | D17: ='7_原始输入'!B231/1000 -> 8666.176 | E17: ='7_原始输入'!B232/1000 -> 627.751 | F17: ='7_原始输入'!B233/1000 -> 1035.751 | G17: ='7_原始输入'!B234/1000 -> 1360.114
A18: 流动资产 | B18: 未取得 | C18: ='7_原始输入'!B235/1000 -> 5073.473 | D18: ='7_原始输入'!B236/1000 -> 5370.023 | E18: ='7_原始输入'!B237/1000 -> 7287.995 | F18: ='7_原始输入'!B238/1000 -> 8210.324 | G18: ='7_原始输入'!B239/1000 -> 6628.076
A19: 流动负债 | B19: 未取得 | C19: 未取得 | D19: ='7_原始输入'!B240/1000 -> 8591.413 | E19: ='7_原始输入'!B241/1000 -> 542.489 | F19: ='7_原始输入'!B242/1000 -> 1001.301 | G19: ='7_原始输入'!B243/1000 -> 1236.732
A20: 应收拨备 | B20: 未取得 | C20: 未取得 | D20: 未取得 | E20: 未取得 | F20: ='7_原始输入'!B244/1000 -> 69.795 | G20: ='7_原始输入'!B245/1000 -> 66.058
A21: 合同资产拨备 | B21: 未取得 | C21: 未取得 | D21: 未取得 | E21: 未取得 | F21: ='7_原始输入'!B246/1000 -> 23.91 | G21: ='7_原始输入'!B247/1000 -> 23.495
A22: 固定资产 | B22: 未取得 | C22: ='7_原始输入'!B248/1000 -> 113.878 | D22: ='7_原始输入'!B249/1000 -> 98.574 | E22: ='7_原始输入'!B250/1000 -> 178.179 | F22: ='7_原始输入'!B251/1000 -> 378.769 | G22: ='7_原始输入'!B252/1000 -> 573.233
A23: 回售期权负债 | B23: 未取得 | C23: ='7_原始输入'!B253/1000 -> 39.812 | D23: ='7_原始输入'!B254/1000 -> 40.449 | E23: ='7_原始输入'!B255/1000 -> 41.099 | F23: ='7_原始输入'!B256/1000 -> 43.3 | G23: ='7_原始输入'!B257/1000 -> 31.681
A26: 资产负债表勾稽差 | C26: =C2-C3-C17 -> 0 | D26: =D2-D3-D17 -> 0 | E26: =E2-E3-E17 -> 2.2737368e-13 | F26: =F2-F3-F17 -> -6.8212103e-13 | G26: =G2-G3-G17 -> 4.5474735e-13
A27: 流动性池：现金+定存+流动FVTPL | C27: =C4+C11+C12 -> 4509.507 | D27: =D4+D11+D12 -> 4528.473 | E27: =E4+E11+E12 -> 6573.594 | F27: =F4+F11+F12 -> 7111.957 | G27: =G4+G11+G12 -> 5377.112
A28: 有息债务含租赁 | C28: =SUM(C5:C8) -> 67.873 | D28: =SUM(D5:D8) -> 53.407 | E28: =SUM(E5:E8) -> 143.018 | F28: =SUM(F5:F8) -> 379.424 | G28: =SUM(G5:G8) -> 615.834
A29: 现金/短贷 | E29: =E4/E5 -> 142.18662 | F29: =F4/F5 -> 20.558325 | G29: =G4/G5 -> 8.8136078
A30: 贸易应收+合同资产/资产 | C30: =(C9+C10)/C2 -> 0.061088786 | D30: =(D9+D10)/D2 -> 0.062298348 | E30: =(E9+E10)/E2 -> 0.036472627 | F30: =(F9+F10)/F2 -> 0.054324538 | G30: =(G9+G10)/G2 -> 0.061857288
A31: 贸易应收拨备率 | F31: =F20/(F9+F20) -> 0.13121087 | G31: =G20/(G9+G20) -> 0.12659082
A32: 合同资产拨备率 | F32: =F21/(F10+F21) -> 0.50640686 | G32: =G21/(G10+G21) -> 0.49505889
A33: 两类合计拨备率 | F33: =(F20+F21)/(F9+F10+F20+F21) -> 0.16179886 | G33: =(G20+G21)/(G9+G10+G20+G21) -> 0.15730868

Sheet 5_估值对比
A1: 同日价、H1 2026；USD百万 | B1: 收盘USD | C1: 市值 | D1: H1收入 | E1: H1毛利率 | F1: H1 OCF | G1: H1 FCF | H1: 现金等价物 | I1: 流动性池 | J1: 静态FCF月数 | K1: 归母PB
A2: WRD | B2: ='7_原始输入'!B285 -> 5.51 | C2: ='7_原始输入'!B286/1000000 -> 1812.5482 | D2: ='7_原始输入'!B100/1000/'7_原始输入'!B277 -> 50.973014 | E2: ='2_利润表五年'!G12 -> 0.36568004 | F2: ='3_现金流照妖镜'!G2/'7_原始输入'!B277 -> -105.47774 | G2: ='3_现金流照妖镜'!G6/'7_原始输入'!B277 -> -140.29668 | H2: ='4_资产负债偿债'!G4/'7_原始输入'!B277 -> 630.0591 | I2: ='4_资产负债偿债'!G27/'7_原始输入'!B277 -> 792.48825 | J2: =I2/(-G2/'7_原始输入'!B280) -> 33.89196 | K2: =C2/('4_资产负债偿债'!G3/'7_原始输入'!B277) -> 1.9230243
A3: PONY | B3: ='7_原始输入'!B289 -> 6.55 | C3: ='7_原始输入'!B290/1000000 -> 2845.4092 | D3: ='7_原始输入'!B297/1000 -> 70.47 | E3: ='7_原始输入'!B299/'7_原始输入'!B297 -> 0.16902228 | F3: ='7_原始输入'!B303/1000 -> -118.215 | G3: =('7_原始输入'!B303-'7_原始输入'!B305)/1000 -> -162.833 | H3: ='7_原始输入'!B307/1000 -> 327.111 | I3: =('7_原始输入'!B307+'7_原始输入'!B308)/1000 -> 1114.119 | J3: =I3/(-G3/'7_原始输入'!B280) -> 41.052575 | K3: =C3/('7_原始输入'!B312/1000) -> 1.8059967
A4: AUR | B4: ='7_原始输入'!B293 -> 6.36 | C4: ='7_原始输入'!B294/1000000 -> 12746.428 | D4: 未取财务；不可排序 | E4: 未取财务；不可排序 | F4: 未取财务；不可排序 | G4: 未取财务；不可排序 | H4: 未取财务；不可排序 | I4: 未取财务；不可排序 | J4: 未取财务；不可排序 | K4: 未取财务；不可排序
A6: WRD为IFRS，另加融资中租赁/利息后可支配FCF压力（USD百万） | B6: =('3_现金流照妖镜'!G6-'3_现金流照妖镜'!B25)/'7_原始输入'!B277 -> -144.66198
A7: WRD上述支出压力跑道（月） | B7: =I2/(-B6/'7_原始输入'!B280) -> 32.869241
A8: WRD现金等价物跑道（月） | B8: =H2/(-G2/'7_原始输入'!B280) -> 26.945432
A9: PONY现金等价物跑道（月） | B9: =H3/(-G3/'7_原始输入'!B280) -> 12.053245
A11: 流动性池不含受限、长期投资；短期投资与定存信用/价格风险不同，不能称完全同风险现金。
A12: 双方现金流准则及capex定义仍有边界差异；PONY capex按公司Non-GAAP，未取得完整租赁附注。

Sheet 5b_股价与估值
A2: WRD价格USD | B2: ='7_原始输入'!B285 -> 5.51
A3: WRD ADS等值股份（扣库存股） | B3: =('7_原始输入'!B258+'7_原始输入'!B259-'7_原始输入'!B260)/'7_原始输入'!B261 -> 3.2895612e+08
A4: 最新归母权益/ADS USD | B4: ='4_资产负债偿债'!G3*1000000/'7_原始输入'!B277/B3 -> 2.8652784
A5: 每ADS现金USD（非底价） | B5: ='4_资产负债偿债'!G4*1000000/'7_原始输入'!B277/B3 -> 1.9153287
A6: 每ADS流动性池USD（非底价） | B6: ='4_资产负债偿债'!G27*1000000/'7_原始输入'!B277/B3 -> 2.4091002
A7: TTM收入人民币百万 | B7: ='2_利润表五年'!H2 -> 830.829
A8: 市值USD百万 | B8: ='7_原始输入'!B286/1000000 -> 1812.5482
A9: TTM PS | B9: =B8/(B7/'7_原始输入'!B277) -> 14.80247
A10: H1现金池/FCF 静态月数 | B10: ='5_估值对比'!J2 -> 33.89196
A11: TTM现金池/FCF 静态月数 | B11: ='4_资产负债偿债'!G27/(-'3_现金流照妖镜'!I6/'7_原始输入'!B281) -> 37.422484
A12: FCF消耗增50%的静态月数 | B12: =B10/'7_原始输入'!B284 -> 22.59464
A13: 回购重复一次半年节奏的静态月数 | B13: ='4_资产负债偿债'!G27/('3_现金流照妖镜'!B26/'7_原始输入'!B280) -> 19.361224
A14: 价格样本数 | B14: =COUNT('8_股价日线'!B2:B474) -> 473
A15: 低于现价的价格数值分位 | B15: =SUM('8_股价日线'!C2:C474)/B14 -> 0.010570825
A16: 日样本折年 | B16: =B14/'7_原始输入'!B282 -> 1.9385246
A17: ADS股本接口勾稽差 | B17: =B3-'7_原始输入'!B287 -> -0.0033333302
A18: 研究观察价USD | B18: ='7_原始输入'!B283 -> 3.3
A19: TTM贸易应收/收入 | B19: ='4_资产负债偿债'!G9/B7 -> 0.54856655
A21: 十年权益PS反推（2036终点；不另加现金，非目标价/非公司指引）
A22: 情景 | B22: 增速下沿 | C22: 增速上沿 | D22: 退出PS下沿 | E22: 退出PS上沿 | F22: 股数累计增幅 | G22: 反推价下沿USD | H22: 反推价上沿USD
A23: 悲观 | B23: ='7_原始输入'!B341 -> 0.1 | C23: ='7_原始输入'!B342 -> 0.15 | D23: ='7_原始输入'!B343 -> 1 | E23: ='7_原始输入'!B344 -> 2 | F23: ='7_原始输入'!B345 -> 0.35 | G23: =$B$7*(1+B23)^'7_原始输入'!B279*D23/'7_原始输入'!B277*1000000/($B$3*(1+F23))/(1+'7_原始输入'!B278)^'7_原始输入'!B279 -> 0.27572977 | H23: =$B$7*(1+C23)^'7_原始输入'!B279*E23/'7_原始输入'!B277*1000000/($B$3*(1+F23))/(1+'7_原始输入'!B278)^'7_原始输入'!B279 -> 0.86013219
A24: 中性 | B24: ='7_原始输入'!B346 -> 0.25 | C24: ='7_原始输入'!B347 -> 0.3 | D24: ='7_原始输入'!B348 -> 3 | E24: ='7_原始输入'!B349 -> 4 | F24: ='7_原始输入'!B350 -> 0.2 | G24: =$B$7*(1+B24)^'7_原始输入'!B279*D24/'7_原始输入'!B277*1000000/($B$3*(1+F24))/(1+'7_原始输入'!B278)^'7_原始输入'!B279 -> 3.3414172 | H24: =$B$7*(1+C24)^'7_原始输入'!B279*E24/'7_原始输入'!B277*1000000/($B$3*(1+F24))/(1+'7_原始输入'!B278)^'7_原始输入'!B279 -> 6.5948184
A25: 乐观 | B25: ='7_原始输入'!B351 -> 0.35 | C25: ='7_原始输入'!B352 -> 0.4 | D25: ='7_原始输入'!B353 -> 5 | E25: ='7_原始输入'!B354 -> 6 | F25: ='7_原始输入'!B355 -> 0.1 | G25: =$B$7*(1+B25)^'7_原始输入'!B279*D25/'7_原始输入'!B277*1000000/($B$3*(1+F25))/(1+'7_原始输入'!B278)^'7_原始输入'!B279 -> 13.116126 | H25: =$B$7*(1+C25)^'7_原始输入'!B279*E25/'7_原始输入'!B277*1000000/($B$3*(1+F25))/(1+'7_原始输入'!B278)^'7_原始输入'!B279 -> 22.642767
A28: 现价在中性退出PS下沿/上沿的隐含十年收入CAGR | B28: =($B$2*$B$3*(1+$F$24)*(1+'7_原始输入'!B278)^'7_原始输入'!B279*'7_原始输入'!B277/1000000/($B$7*$D$24))^(1/'7_原始输入'!B279)-1 -> 0.31411116 | C28: =($B$2*$B$3*(1+$F$24)*(1+'7_原始输入'!B278)^'7_原始输入'!B279*'7_原始输入'!B277/1000000/($B$7*$E$24))^(1/'7_原始输入'!B279)-1 -> 0.27684514
A30: PB档位敏感度（账面机械映射，非价值底）
A31: ='7_原始输入'!B356 -> 0.8 | B31: =A31*$B$4 -> 2.2922228
A32: ='7_原始输入'!B357 -> 1 | B32: =A32*$B$4 -> 2.8652784
A33: ='7_原始输入'!B358 -> 1.5 | B33: =A33*$B$4 -> 4.2979177
A34: ='7_原始输入'!B359 -> 2 | B34: =A34*$B$4 -> 5.7305569
A36: 期权/RSU不直接加到股本：预发行激励股份可能重叠；用20%等累计稀释假设测试，不称完全摊薄。

Sheet 6_取数日志
A1: 采集日 | B1: 指标/输入单元格 | C1: 原值 | D1: 来源及页码 | E1: 口径
A2: 2026-09-17 | B2: FY2021_收入 / 7_原始输入!B2 | C2: 138172 | D2: 2024_US_424B4 PDF页279/F-3；286–287/F-10–11；https://ir.weride.ai/static-files/406cbf25-bb49-4020-b913-f9cca1283c6e | E2: 审计披露；单位：人民币千元
A3: 2026-09-17 | B3: FY2022_收入 / 7_原始输入!B3 | C3: 527543 | D3: FY2024_20F PDF页169/F-3；176–177/F-10–11；https://ir.weride.ai/static-files/72a895d1-7999-4f63-9d97-476c54e7ecab | E3: 审计披露；单位：人民币千元
A4: 2026-09-17 | B4: FY2023_收入 / 7_原始输入!B4 | C4: 401844 | D4: FY2025_20F PDF页171/F-4；178/F-11；111/108；https://ir.weride.ai/system/files-encrypted/nasdaq_kms/assets/2026/04/23/10-08-17/20-F.pdf | E4: 审计披露；单位：人民币千元
A5: 2026-09-17 | B5: FY2024_收入 / 7_原始输入!B5 | C5: 361134 | D5: FY2025_20F PDF页171/F-4；178/F-11；111/108；https://ir.weride.ai/system/files-encrypted/nasdaq_kms/assets/2026/04/23/10-08-17/20-F.pdf | E5: 审计披露；单位：人民币千元
A6: 2026-09-17 | B6: FY2025_收入 / 7_原始输入!B6 | C6: 684587 | D6: FY2025_20F PDF页171/F-4；178/F-11；111/108；https://ir.weride.ai/system/files-encrypted/nasdaq_kms/assets/2026/04/23/10-08-17/20-F.pdf | E6: 审计披露；单位：人民币千元
A7: 2026-09-17 | B7: FY2021_产品 / 7_原始输入!B7 | C7: 101597 | D7: 2024_US_424B4 PDF页279/F-3；286–287/F-10–11；https://ir.weride.ai/static-files/406cbf25-bb49-4020-b913-f9cca1283c6e | E7: 审计披露；单位：人民币千元
A8: 2026-09-17 | B8: FY2022_产品 / 7_原始输入!B8 | C8: 337717 | D8: FY2024_20F PDF页169/F-3；176–177/F-10–11；https://ir.weride.ai/static-files/72a895d1-7999-4f63-9d97-476c54e7ecab | E8: 审计披露；单位：人民币千元
A9: 2026-09-17 | B9: FY2023_产品 / 7_原始输入!B9 | C9: 54190 | D9: FY2025_20F PDF页171/F-4；178/F-11；111/108；https://ir.weride.ai/system/files-encrypted/nasdaq_kms/assets/2026/04/23/10-08-17/20-F.pdf | E9: 审计披露；单位：人民币千元
A10: 2026-09-17 | B10: FY2024_产品 / 7_原始输入!B10 | C10: 87710 | D10: FY2025_20F PDF页171/F-4；178/F-11；111/108；https://ir.weride.ai/system/files-encrypted/nasdaq_kms/assets/2026/04/23/10-08-17/20-F.pdf | E10: 审计披露；单位：人民币千元
A11: 2026-09-17 | B11: FY2025_产品 / 7_原始输入!B11 | C11: 359843 | D11: FY2025_20F PDF页171/F-4；178/F-11；111/108；https://ir.weride.ai/system/files-encrypted/nasdaq_kms/assets/2026/04/23/10-08-17/20-F.pdf | E11: 审计披露；单位：人民币千元
A12: 2026-09-17 | B12: FY2021_服务 / 7_原始输入!B12 | C12: 36575 | D12: 2024_US_424B4 PDF页279/F-3；286–287/F-10–11；https://ir.weride.ai/static-files/406cbf25-bb49-4020-b913-f9cca1283c6e | E12: 审计披露；单位：人民币千元
A13: 2026-09-17 | B13: FY2022_服务 / 7_原始输入!B13 | C13: 189826 | D13: FY2024_20F PDF页169/F-3；176–177/F-10–11；https://ir.weride.ai/static-files/72a895d1-7999-4f63-9d97-476c54e7ecab | E13: 审计披露；单位：人民币千元
... A359: 2026-09-17 | B359: PB档2 / 7_原始输入!B359 | C359: 2 | D359: 本报告账面敏感性假设 | E359: 假设；单位：倍
A360: 2026-09-17 | B360: 8_股价日线!B2:B474 | C360: 逐日收盘；见CSV | D360: https://push2his.eastmoney.com/api/qt/stock/kline/get?secid=105.WRD&klt=101&fqt=0&beg=20241001&end=20260916&lmt=1000&fields1=f1%2Cf2%2Cf3%2Cf4%2Cf5%2Cf6&fields2=f51%2Cf52%2Cf53%2Cf54%2Cf55%2Cf56%2Cf57%2Cf58%2Cf59%2Cf60%2Cf61 | E360: 批量逐行来源相同；不复权；每行日期为有效日

Sheet 7_原始输入
A1: 键 | B1: 原值 | C1: 单位 | D1: 来源及页码 | E1: 证据等级/口径
A2: FY2021_收入 | B2: 138172 | C2: 人民币千元 | D2: 2024_US_424B4 PDF页279/F-3；286–287/F-10–11；https://ir.weride.ai/static-files/406cbf25-bb49-4020-b913-f9cca1283c6e | E2: 审计披露
A3: FY2022_收入 | B3: 527543 | C3: 人民币千元 | D3: FY2024_20F PDF页169/F-3；176–177/F-10–11；https://ir.weride.ai/static-files/72a895d1-7999-4f63-9d97-476c54e7ecab | E3: 审计披露
A4: FY2023_收入 | B4: 401844 | C4: 人民币千元 | D4: FY2025_20F PDF页171/F-4；178/F-11；111/108；https://ir.weride.ai/system/files-encrypted/nasdaq_kms/assets/2026/04/23/10-08-17/20-F.pdf | E4: 审计披露
A5: FY2024_收入 | B5: 361134 | C5: 人民币千元 | D5: FY2025_20F PDF页171/F-4；178/F-11；111/108；https://ir.weride.ai/system/files-encrypted/nasdaq_kms/assets/2026/04/23/10-08-17/20-F.pdf | E5: 审计披露
A6: FY2025_收入 | B6: 684587 | C6: 人民币千元 | D6: FY2025_20F PDF页171/F-4；178/F-11；111/108；https://ir.weride.ai/system/files-encrypted/nasdaq_kms/assets/2026/04/23/10-08-17/20-F.pdf | E6: 审计披露
A7: FY2021_产品 | B7: 101597 | C7: 人民币千元 | D7: 2024_US_424B4 PDF页279/F-3；286–287/F-10–11；https://ir.weride.ai/static-files/406cbf25-bb49-4020-b913-f9cca1283c6e | E7: 审计披露
A8: FY2022_产品 | B8: 337717 | C8: 人民币千元 | D8: FY2024_20F PDF页169/F-3；176–177/F-10–11；https://ir.weride.ai/static-files/72a895d1-7999-4f63-9d97-476c54e7ecab | E8: 审计披露
A9: FY2023_产品 | B9: 54190 | C9: 人民币千元 | D9: FY2025_20F PDF页171/F-4；178/F-11；111/108；https://ir.weride.ai/system/files-encrypted/nasdaq_kms/assets/2026/04/23/10-08-17/20-F.pdf | E9: 审计披露
A10: FY2024_产品 | B10: 87710 | C10: 人民币千元 | D10: FY2025_20F PDF页171/F-4；178/F-11；111/108；https://ir.weride.ai/system/files-encrypted/nasdaq_kms/assets/2026/04/23/10-08-17/20-F.pdf | E10: 审计披露
A11: FY2025_产品 | B11: 359843 | C11: 人民币千元 | D11: FY2025_20F PDF页171/F-4；178/F-11；111/108；https://ir.weride.ai/system/files-encrypted/nasdaq_kms/assets/2026/04/23/10-08-17/20-F.pdf | E11: 审计披露
A12: FY2021_服务 | B12: 36575 | C12: 人民币千元 | D12: 2024_US_424B4 PDF页279/F-3；286–287/F-10–11；https://ir.weride.ai/static-files/406cbf25-bb49-4020-b913-f9cca1283c6e | E12: 审计披露
A13: FY2022_服务 | B13: 189826 | C13: 人民币千元 | D13: FY2024_20F PDF页169/F-3；176–177/F-10–11；https://ir.weride.ai/static-files/72a895d1-7999-4f63-9d97-476c54e7ecab | E13: 审计披露
... A359: PB档2 | B359: 2 | C359: 倍 | D359: 本报告账面敏感性假设 | E359: 假设

Sheet 8_股价日线
A1: 日期 | B1: WRD收盘USD（不复权） | C1: 严格低于基准价
A2: 2024-10-25 | B2: 16.55 | C2: =--(B2<'5b_股价与估值'!B2) -> 0
A3: 2024-10-28 | B3: 17 | C3: =--(B3<'5b_股价与估值'!B2) -> 0
A4: 2024-10-29 | B4: 15.41 | C4: =--(B4<'5b_股价与估值'!B2) -> 0
A5: 2024-10-30 | B5: 15.25 | C5: =--(B5<'5b_股价与估值'!B2) -> 0
A6: 2024-10-31 | B6: 14.77 | C6: =--(B6<'5b_股价与估值'!B2) -> 0
A7: 2024-11-01 | B7: 14.52 | C7: =--(B7<'5b_股价与估值'!B2) -> 0
A8: 2024-11-04 | B8: 15.46 | C8: =--(B8<'5b_股价与估值'!B2) -> 0
A9: 2024-11-05 | B9: 15.57 | C9: =--(B9<'5b_股价与估值'!B2) -> 0
A10: 2024-11-06 | B10: 15.51 | C10: =--(B10<'5b_股价与估值'!B2) -> 0
A11: 2024-11-07 | B11: 15.66 | C11: =--(B11<'5b_股价与估值'!B2) -> 0
A12: 2024-11-08 | B12: 15.5 | C12: =--(B12<'5b_股价与估值'!B2) -> 0
A13: 2024-11-11 | B13: 22.47 | C13: =--(B13<'5b_股价与估值'!B2) -> 0
A14: 2024-11-12 | B14: 17.18 | C14: =--(B14<'5b_股价与估值'!B2) -> 0
A15: 2024-11-13 | B15: 19.04 | C15: =--(B15<'5b_股价与估值'!B2) -> 0
A16: 2024-11-14 | B16: 15.79 | C16: =--(B16<'5b_股价与估值'!B2) -> 0
A17: 2024-11-15 | B17: 17.37 | C17: =--(B17<'5b_股价与估值'!B2) -> 0
A18: 2024-11-18 | B18: 18.33 | C18: =--(B18<'5b_股价与估值'!B2) -> 0
A19: 2024-11-19 | B19: 19.29 | C19: =--(B19<'5b_股价与估值'!B2) -> 0
A20: 2024-11-20 | B20: 17.7 | C20: =--(B20<'5b_股价与估值'!B2) -> 0
A21: 2024-11-21 | B21: 18.2 | C21: =--(B21<'5b_股价与估值'!B2) -> 0
A22: 2024-11-22 | B22: 19.865 | C22: =--(B22<'5b_股价与估值'!B2) -> 0
A23: 2024-11-25 | B23: 18.27 | C23: =--(B23<'5b_股价与估值'!B2) -> 0
A24: 2024-11-26 | B24: 17.5 | C24: =--(B24<'5b_股价与估值'!B2) -> 0
A25: 2024-11-27 | B25: 17.16 | C25: =--(B25<'5b_股价与估值'!B2) -> 0
A26: 2024-11-29 | B26: 17.37 | C26: =--(B26<'5b_股价与估值'!B2) -> 0
A27: 2024-12-02 | B27: 16.73 | C27: =--(B27<'5b_股价与估值'!B2) -> 0
A28: 2024-12-03 | B28: 17.14 | C28: =--(B28<'5b_股价与估值'!B2) -> 0
A29: 2024-12-04 | B29: 16.94 | C29: =--(B29<'5b_股价与估值'!B2) -> 0
A30: 2024-12-05 | B30: 15.95 | C30: =--(B30<'5b_股价与估值'!B2) -> 0
A31: 2024-12-06 | B31: 16.81 | C31: =--(B31<'5b_股价与估值'!B2) -> 0
A32: 2024-12-09 | B32: 17.16 | C32: =--(B32<'5b_股价与估值'!B2) -> 0
A33: 2024-12-10 | B33: 15.92 | C33: =--(B33<'5b_股价与估值'!B2) -> 0
A34: 2024-12-11 | B34: 16 | C34: =--(B34<'5b_股价与估值'!B2) -> 0
A35: 2024-12-12 | B35: 16.04 | C35: =--(B35<'5b_股价与估值'!B2) -> 0
A36: 2024-12-13 | B36: 16.2 | C36: =--(B36<'5b_股价与估值'!B2) -> 0
A37: 2024-12-16 | B37: 16 | C37: =--(B37<'5b_股价与估值'!B2) -> 0
A38: 2024-12-17 | B38: 15.66 | C38: =--(B38<'5b_股价与估值'!B2) -> 0
A39: 2024-12-18 | B39: 14.68 | C39: =--(B39<'5b_股价与估值'!B2) -> 0
A40: 2024-12-19 | B40: 15.07 | C40: =--(B40<'5b_股价与估值'!B2) -> 0
...
